Workbook

Sheet Recruitment_Data
A1: Candidate_ID | B1: Source | C1: Department | D1: Role | E1: Applied_Date | F1: Stage | G1: Stage_Entry_Date | H1: Stage_Exit_Date | I1: Hiring_Cost_INR | J1: Final_Status | K1: Stage_Duration_Days | L1: Time_to_Hire_Days | M1: Hired_Flag | N1: Offer_Flag
A2: CAND1001 | B2: Campus | C2: IT | D2: IT Analyst | E2: 45803 | F2: Interviewed | G2: 45808 | H2: 45812 | I2: 4411 | J2: Rejected | K2: =H2-G2 | M2: 0 | N2: 0
A3: CAND1002 | B3: Referral | C3: HR | D3: HR Analyst | E3: 45821 | F3: Rejected | G3: 45823 | H3: 45830 | I3: 4491 | J3: Rejected | K3: =H3-G3 | M3: 0 | N3: 0
A4: CAND1003 | B4: Referral | C4: Operations | D4: Operations Manager | E4: 46011 | F4: Interviewed | G4: 46016 | H4: 46017 | I4: 10918 | J4: Rejected | K4: =H4-G4 | M4: 0 | N4: 0
A5: CAND1004 | B5: Campus | C5: Finance | D5: Finance Executive | E5: 45979 | F5: Interviewed | G5: 45984 | H5: 45987 | I5: 6956 | J5: Rejected | K5: =H5-G5 | M5: 0 | N5: 0
A6: CAND1005 | B6: Referral | C6: Marketing | D6: Marketing Manager | E6: 45765 | F6: Screened | G6: 45775 | H6: 45782 | I6: 22222 | J6: Rejected | K6: =H6-G6 | M6: 0 | N6: 0
A7: CAND1006 | B7: LinkedIn | C7: Marketing | D7: Marketing Executive | E7: 45849 | F7: Interviewed | G7: 45858 | H7: 45861 | I7: 17399 | J7: Rejected | K7: =H7-G7 | M7: 0 | N7: 0
A8: CAND1007 | B8: Campus | C8: HR | D8: HR Analyst | E8: 45946 | F8: Rejected | G8: 45950 | H8: 45951 | I8: 7620 | J8: Rejected | K8: =H8-G8 | M8: 0 | N8: 0
A9: CAND1008 | B9: Referral | C9: Sales | D9: Sales Manager | E9: 45753 | F9: Hired | G9: 45759 | H9: 45764 | I9: 36241 | J9: Hired | K9: =H9-G9 | L9: 11 | M9: 1 | N9: 1
A10: CAND1009 | B10: Referral | C10: Sales | D10: Sales Executive | E10: 45809 | F10: Rejected | G10: 45816 | H10: 45819 | I10: 18616 | J10: Rejected | K10: =H10-G10 | M10: 0 | N10: 0
A11: CAND1010 | B11: Job Portal | C11: Operations | D11: Operations Manager | E11: 45903 | F11: Rejected | G11: 45909 | H11: 45911 | I11: 19881 | J11: Rejected | K11: =H11-G11 | M11: 0 | N11: 0
A12: CAND1011 | B12: Campus | C12: Operations | D12: Operations Analyst | E12: 46011 | F12: Rejected | G12: 46017 | H12: 46020 | I12: 17062 | J12: Rejected | K12: =H12-G12 | M12: 0 | N12: 0
A13: CAND1012 | B13: Job Portal | C13: HR | D13: HR Analyst | E13: 45787 | F13: Hired | G13: 45790 | H13: 45793 | I13: 39092 | J13: Hired | K13: =H13-G13 | L13: 6 | M13: 1 | N13: 1
A14: CAND1013 | B14: Job Portal | C14: Marketing | D14: Marketing Executive | E14: 45904 | F14: Screened | G14: 45907 | H14: 45914 | I14: 10116 | J14: Rejected | K14: =H14-G14 | M14: 0 | N14: 0
A15: CAND1014 | B15: Job Portal | C15: Sales | D15: Sales Analyst | E15: 45754 | F15: Hired | G15: 45756 | H15: 45757 | I15: 25541 | J15: Hired | K15: =H15-G15 | L15: 3 | M15: 1 | N15: 1
A16: CAND1015 | B16: Referral | C16: Sales | D16: Sales Manager | E16: 45913 | F16: Rejected | G16: 45920 | H16: 45921 | I16: 19953 | J16: Rejected | K16: =H16-G16 | M16: 0 | N16: 0
A17: CAND1016 | B17: LinkedIn | C17: Marketing | D17: Marketing Manager | E17: 45759 | F17: Rejected | G17: 45762 | H17: 45763 | I17: 22611 | J17: Rejected | K17: =H17-G17 | M17: 0 | N17: 0
A18: CAND1017 | B18: Campus | C18: Operations | D18: Operations Manager | E18: 45883 | F18: Screened | G18: 45887 | H18: 45889 | I18: 17103 | J18: Rejected | K18: =H18-G18 | M18: 0 | N18: 0
A19: CAND1018 | B19: Referral | C19: HR | D19: HR Analyst | E19: 45731 | F19: Offered | G19: 45740 | H19: 45746 | I19: 10076 | J19: Rejected | K19: =H19-G19 | M19: 0 | N19: 1
A20: CAND1019 | B20: LinkedIn | C20: Marketing | D20: Marketing Executive | E20: 45898 | F20: Interviewed | G20: 45900 | H20: 45902 | I20: 7905 | J20: Rejected | K20: =H20-G20 | M20: 0 | N20: 0
A21: CAND1020 | B21: LinkedIn | C21: HR | D21: HR Executive | E21: 45832 | F21: Rejected | G21: 45835 | H21: 45842 | I21: 7033 | J21: Rejected | K21: =H21-G21 | M21: 0 | N21: 0
A22: CAND1021 | B22: Job Portal | C22: IT | D22: IT Analyst | E22: 45923 | F22: Screened | G22: 45925 | H22: 45928 | I22: 18625 | J22: Rejected | K22: =H22-G22 | M22: 0 | N22: 0
A23: CAND1022 | B23: Campus | C23: Sales | D23: Sales Analyst | E23: 45670 | F23: Rejected | G23: 45673 | H23: 45674 | I23: 22070 | J23: Rejected | K23: =H23-G23 | M23: 0 | N23: 0
A24: CAND1023 | B24: Job Portal | C24: Marketing | D24: Marketing Analyst | E24: 45983 | F24: Offered | G24: 45987 | H24: 45991 | I24: 7972 | J24: Rejected | K24: =H24-G24 | M24: 0 | N24: 1
A25: CAND1024 | B25: Job Portal | C25: HR | D25: HR Manager | E25: 45947 | F25: Rejected | G25: 45956 | H25: 45959 | I25: 7843 | J25: Rejected | K25: =H25-G25 | M25: 0 | N25: 0
A26: CAND1025 | B26: Job Portal | C26: HR | D26: HR Manager | E26: 45992 | F26: Screened | G26: 45996 | H26: 45998 | I26: 4550 | J26: Rejected | K26: =H26-G26 | M26: 0 | N26: 0
A27: CAND1026 | B27: Referral | C27: Operations | D27: Operations Analyst | E27: 45684 | F27: Interviewed | G27: 45693 | H27: 45694 | I27: 20450 | J27: Rejected | K27: =H27-G27 | M27: 0 | N27: 0
A28: CAND1027 | B28: Referral | C28: Operations | D28: Operations Executive | E28: 45806 | F28: Hired | G28: 45808 | H28: 45809 | I28: 33499 | J28: Hired | K28: =H28-G28 | L28: 3 | M28: 1 | N28: 1
A29: CAND1028 | B29: Job Portal | C29: IT | D29: IT Analyst | E29: 45820 | F29: Screened | G29: 45830 | H29: 45832 | I29: 12531 | J29: Rejected | K29: =H29-G29 | M29: 0 | N29: 0
A30: CAND1029 | B30: Referral | C30: Sales | D30: Sales Manager | E30: 45824 | F30: Interviewed | G30: 45830 | H30: 45837 | I30: 5105 | J30: Rejected | K30: =H30-G30 | M30: 0 | N30: 0
A31: CAND1030 | B31: Referral | C31: IT | D31: IT Analyst | E31: 45709 | F31: Rejected | G31: 45714 | H31: 45716 | I31: 23483 | J31: Rejected | K31: =H31-G31 | M31: 0 | N31: 0
A32: CAND1031 | B32: LinkedIn | C32: Finance | D32: Finance Analyst | E32: 45886 | F32: Hired | G32: 45896 | H32: 45897 | I32: 22568 | J32: Hired | K32: =H32-G32 | L32: 11 | M32: 1 | N32: 1
A33: CAND1032 | B33: LinkedIn | C33: IT | D33: IT Executive | E33: 45942 | F33: Rejected | G33: 45948 | H33: 45949 | I33: 7882 | J33: Rejected | K33: =H33-G33 | M33: 0 | N33: 0
A34: CAND1033 | B34: LinkedIn | C34: IT | D34: IT Analyst | E34: 45909 | F34: Interviewed | G34: 45911 | H34: 45914 | I34: 23334 | J34: Rejected | K34: =H34-G34 | M34: 0 | N34: 0
A35: CAND1034 | B35: Referral | C35: HR | D35: HR Analyst | E35: 45850 | F35: Screened | G35: 45857 | H35: 45858 | I35: 4339 | J35: Rejected | K35: =H35-G35 | M35: 0 | N35: 0
A36: CAND1035 | B36: LinkedIn | C36: Sales | D36: Sales Analyst | E36: 45849 | F36: Hired | G36: 45855 | H36: 45856 | I36: 40054 | J36: Hired | K36: =H36-G36 | L36: 7 | M36: 1 | N36: 1
A37: CAND1036 | B37: Job Portal | C37: Operations | D37: Operations Executive | E37: 46000 | F37: Interviewed | G37: 46004 | H37: 46011 | I37: 15547 | J37: Rejected | K37: =H37-G37 | M37: 0 | N37: 0
A38: CAND1037 | B38: Campus | C38: Operations | D38: Operations Executive | E38: 45672 | F38: Rejected | G38: 45681 | H38: 45682 | I38: 15060 | J38: Rejected | K38: =H38-G38 | M38: 0 | N38: 0
A39: CAND1038 | B39: Job Portal | C39: IT | D39: IT Analyst | E39: 45969 | F39: Hired | G39: 45975 | H39: 45981 | I39: 19505 | J39: Hired | K39: =H39-G39 | L39: 12 | M39: 1 | N39: 1
A40: CAND1039 | B40: LinkedIn | C40: Finance | D40: Finance Executive | E40: 45808 | F40: Hired | G40: 45817 | H40: 45819 | I40: 22516 | J40: Hired | K40: =H40-G40 | L40: 11 | M40: 1 | N40: 1
...

Sheet KPI_Summary
A1: KPI | B1: Value | C1: Definition
A2: Total Candidates | B2: =COUNTA(Recruitment_Data!A2:A241) | C2: Candidates in dataset
A3: Hires | B3: =COUNTIF(Recruitment_Data!J2:J241,"Hired") | C3: Candidates hired
A4: Application-to-Hire Ratio | B4: =IFERROR(B3/B2,0) | C4: Hired ÷ Applied
A5: Average Time-to-Hire | B5: =IFERROR(AVERAGEIF(Recruitment_Data!J2:J241,"Hired",Recruitment_Data!L2:L241),0) | C5: Days from application to hire
A6: Total Hiring Cost | B6: =SUM(Recruitment_Data!I2:I241) | C6: Total recruitment cost
A7: Cost-per-Hire | B7: =IFERROR(B6/B3,0) | C7: Total cost ÷ hires
A8: Offer Acceptance Rate | B8: =IFERROR(COUNTIF(Recruitment_Data!J2:J241,"Hired")/COUNTIF(Recruitment_Data!F2:F241,"Offered"),0) | C8: Hired ÷ offers

Sheet Funnel_Summary
A1: Stage | B1: Candidates | C1: Conversion % | D1: Drop-Off %
A2: Applied | B2: 240 | C2: 1 | D2: 0
A3: Screened | B3: 187 | C3: 0.77916667 | D3: 0.22083333
A4: Interviewed | B4: 114 | C4: 0.60962567 | D4: 0.39037433
A5: Offered | B5: 54 | C5: 0.47368421 | D5: 0.52631579
A6: Hired | B6: 47 | C6: 0.87037037 | D6: 0.12962963
A7: Rejected | B7: 193 | C7: 0.80416667 | D7: 0.80416667

Sheet Source_Effectiveness
A1: Source | B1: Candidates | C1: Hires | D1: Conversion % | E1: Total Cost (₹) | F1: Cost per Hire (₹) | G1: Avg Time-to-Hire
A2: Job Portal | B2: =COUNTIF(Recruitment_Data!B$2:B$241,A2) | C2: =COUNTIFS(Recruitment_Data!B$2:B$241,A2,Recruitment_Data!J$2:J$241,"Hired") | D2: =IFERROR(C2/B2,0) | E2: =SUMIF(Recruitment_Data!B$2:B$241,A2,Recruitment_Data!I$2:I$241) | F2: =IFERROR(E2/C2,0) | G2: =IFERROR(AVERAGEIFS(Recruitment_Data!L$2:L$241,Recruitment_Data!B$2:B$241,A2,Recruitment_Data!J$2:J$241,"Hired"),0)
A3: Referral | B3: =COUNTIF(Recruitment_Data!B$2:B$241,A3) | C3: =COUNTIFS(Recruitment_Data!B$2:B$241,A3,Recruitment_Data!J$2:J$241,"Hired") | D3: =IFERROR(C3/B3,0) | E3: =SUMIF(Recruitment_Data!B$2:B$241,A3,Recruitment_Data!I$2:I$241) | F3: =IFERROR(E3/C3,0) | G3: =IFERROR(AVERAGEIFS(Recruitment_Data!L$2:L$241,Recruitment_Data!B$2:B$241,A3,Recruitment_Data!J$2:J$241,"Hired"),0)
A4: LinkedIn | B4: =COUNTIF(Recruitment_Data!B$2:B$241,A4) | C4: =COUNTIFS(Recruitment_Data!B$2:B$241,A4,Recruitment_Data!J$2:J$241,"Hired") | D4: =IFERROR(C4/B4,0) | E4: =SUMIF(Recruitment_Data!B$2:B$241,A4,Recruitment_Data!I$2:I$241) | F4: =IFERROR(E4/C4,0) | G4: =IFERROR(AVERAGEIFS(Recruitment_Data!L$2:L$241,Recruitment_Data!B$2:B$241,A4,Recruitment_Data!J$2:J$241,"Hired"),0)
A5: Campus | B5: =COUNTIF(Recruitment_Data!B$2:B$241,A5) | C5: =COUNTIFS(Recruitment_Data!B$2:B$241,A5,Recruitment_Data!J$2:J$241,"Hired") | D5: =IFERROR(C5/B5,0) | E5: =SUMIF(Recruitment_Data!B$2:B$241,A5,Recruitment_Data!I$2:I$241) | F5: =IFERROR(E5/C5,0) | G5: =IFERROR(AVERAGEIFS(Recruitment_Data!L$2:L$241,Recruitment_Data!B$2:B$241,A5,Recruitment_Data!J$2:J$241,"Hired"),0)

Sheet Department_Analysis
A1: Department | B1: Candidates | C1: Hires | D1: Conversion % | E1: Avg Time-to-Hire | F1: Total Cost (₹) | G1: Cost per Hire (₹)
A2: IT | B2: =COUNTIF(Recruitment_Data!C$2:C$241,A2) | C2: =COUNTIFS(Recruitment_Data!C$2:C$241,A2,Recruitment_Data!J$2:J$241,"Hired") | D2: =IFERROR(C2/B2,0) | E2: =IFERROR(AVERAGEIFS(Recruitment_Data!L$2:L$241,Recruitment_Data!C$2:C$241,A2,Recruitment_Data!J$2:J$241,"Hired"),0) | F2: =SUMIF(Recruitment_Data!C$2:C$241,A2,Recruitment_Data!I$2:I$241) | G2: =IFERROR(F2/C2,0)
A3: Finance | B3: =COUNTIF(Recruitment_Data!C$2:C$241,A3) | C3: =COUNTIFS(Recruitment_Data!C$2:C$241,A3,Recruitment_Data!J$2:J$241,"Hired") | D3: =IFERROR(C3/B3,0) | E3: =IFERROR(AVERAGEIFS(Recruitment_Data!L$2:L$241,Recruitment_Data!C$2:C$241,A3,Recruitment_Data!J$2:J$241,"Hired"),0) | F3: =SUMIF(Recruitment_Data!C$2:C$241,A3,Recruitment_Data!I$2:I$241) | G3: =IFERROR(F3/C3,0)
A4: HR | B4: =COUNTIF(Recruitment_Data!C$2:C$241,A4) | C4: =COUNTIFS(Recruitment_Data!C$2:C$241,A4,Recruitment_Data!J$2:J$241,"Hired") | D4: =IFERROR(C4/B4,0) | E4: =IFERROR(AVERAGEIFS(Recruitment_Data!L$2:L$241,Recruitment_Data!C$2:C$241,A4,Recruitment_Data!J$2:J$241,"Hired"),0) | F4: =SUMIF(Recruitment_Data!C$2:C$241,A4,Recruitment_Data!I$2:I$241) | G4: =IFERROR(F4/C4,0)
A5: Sales | B5: =COUNTIF(Recruitment_Data!C$2:C$241,A5) | C5: =COUNTIFS(Recruitment_Data!C$2:C$241,A5,Recruitment_Data!J$2:J$241,"Hired") | D5: =IFERROR(C5/B5,0) | E5: =IFERROR(AVERAGEIFS(Recruitment_Data!L$2:L$241,Recruitment_Data!C$2:C$241,A5,Recruitment_Data!J$2:J$241,"Hired"),0) | F5: =SUMIF(Recruitment_Data!C$2:C$241,A5,Recruitment_Data!I$2:I$241) | G5: =IFERROR(F5/C5,0)
A6: Operations | B6: =COUNTIF(Recruitment_Data!C$2:C$241,A6) | C6: =COUNTIFS(Recruitment_Data!C$2:C$241,A6,Recruitment_Data!J$2:J$241,"Hired") | D6: =IFERROR(C6/B6,0) | E6: =IFERROR(AVERAGEIFS(Recruitment_Data!L$2:L$241,Recruitment_Data!C$2:C$241,A6,Recruitment_Data!J$2:J$241,"Hired"),0) | F6: =SUMIF(Recruitment_Data!C$2:C$241,A6,Recruitment_Data!I$2:I$241) | G6: =IFERROR(F6/C6,0)
A7: Marketing | B7: =COUNTIF(Recruitment_Data!C$2:C$241,A7) | C7: =COUNTIFS(Recruitment_Data!C$2:C$241,A7,Recruitment_Data!J$2:J$241,"Hired") | D7: =IFERROR(C7/B7,0) | E7: =IFERROR(AVERAGEIFS(Recruitment_Data!L$2:L$241,Recruitment_Data!C$2:C$241,A7,Recruitment_Data!J$2:J$241,"Hired"),0) | F7: =SUMIF(Recruitment_Data!C$2:C$241,A7,Recruitment_Data!I$2:I$241) | G7: =IFERROR(F7/C7,0)

Sheet Monthly_Trend
A1: Month | B1: Hires | C1: Avg Time-to-Hire | D1: Hiring Cost (₹)
A2: 45658 | B2: =COUNTIFS(Recruitment_Data!E$2:E$241,">="&A2,Recruitment_Data!E$2:E$241,"<"&EDATE(A2,1),Recruitment_Data!J$2:J$241,"Hired") | C2: =IFERROR(AVERAGEIFS(Recruitment_Data!L$2:L$241,Recruitment_Data!E$2:E$241,">="&A2,Recruitment_Data!E$2:E$241,"<"&EDATE(A2,1),Recruitment_Data!J$2:J$241,"Hired"),0) | D2: =SUMIFS(Recruitment_Data!I$2:I$241,Recruitment_Data!E$2:E$241,">="&A2,Recruitment_Data!E$2:E$241,"<"&EDATE(A2,1),Recruitment_Data!J$2:J$241,"Hired")
A3: 45689 | B3: =COUNTIFS(Recruitment_Data!E$2:E$241,">="&A3,Recruitment_Data!E$2:E$241,"<"&EDATE(A3,1),Recruitment_Data!J$2:J$241,"Hired") | C3: =IFERROR(AVERAGEIFS(Recruitment_Data!L$2:L$241,Recruitment_Data!E$2:E$241,">="&A3,Recruitment_Data!E$2:E$241,"<"&EDATE(A3,1),Recruitment_Data!J$2:J$241,"Hired"),0) | D3: =SUMIFS(Recruitment_Data!I$2:I$241,Recruitment_Data!E$2:E$241,">="&A3,Recruitment_Data!E$2:E$241,"<"&EDATE(A3,1),Recruitment_Data!J$2:J$241,"Hired")
A4: 45717 | B4: =COUNTIFS(Recruitment_Data!E$2:E$241,">="&A4,Recruitment_Data!E$2:E$241,"<"&EDATE(A4,1),Recruitment_Data!J$2:J$241,"Hired") | C4: =IFERROR(AVERAGEIFS(Recruitment_Data!L$2:L$241,Recruitment_Data!E$2:E$241,">="&A4,Recruitment_Data!E$2:E$241,"<"&EDATE(A4,1),Recruitment_Data!J$2:J$241,"Hired"),0) | D4: =SUMIFS(Recruitment_Data!I$2:I$241,Recruitment_Data!E$2:E$241,">="&A4,Recruitment_Data!E$2:E$241,"<"&EDATE(A4,1),Recruitment_Data!J$2:J$241,"Hired")
A5: 45748 | B5: =COUNTIFS(Recruitment_Data!E$2:E$241,">="&A5,Recruitment_Data!E$2:E$241,"<"&EDATE(A5,1),Recruitment_Data!J$2:J$241,"Hired") | C5: =IFERROR(AVERAGEIFS(Recruitment_Data!L$2:L$241,Recruitment_Data!E$2:E$241,">="&A5,Recruitment_Data!E$2:E$241,"<"&EDATE(A5,1),Recruitment_Data!J$2:J$241,"Hired"),0) | D5: =SUMIFS(Recruitment_Data!I$2:I$241,Recruitment_Data!E$2:E$241,">="&A5,Recruitment_Data!E$2:E$241,"<"&EDATE(A5,1),Recruitment_Data!J$2:J$241,"Hired")
A6: 45778 | B6: =COUNTIFS(Recruitment_Data!E$2:E$241,">="&A6,Recruitment_Data!E$2:E$241,"<"&EDATE(A6,1),Recruitment_Data!J$2:J$241,"Hired") | C6: =IFERROR(AVERAGEIFS(Recruitment_Data!L$2:L$241,Recruitment_Data!E$2:E$241,">="&A6,Recruitment_Data!E$2:E$241,"<"&EDATE(A6,1),Recruitment_Data!J$2:J$241,"Hired"),0) | D6: =SUMIFS(Recruitment_Data!I$2:I$241,Recruitment_Data!E$2:E$241,">="&A6,Recruitment_Data!E$2:E$241,"<"&EDATE(A6,1),Recruitment_Data!J$2:J$241,"Hired")
A7: 45809 | B7: =COUNTIFS(Recruitment_Data!E$2:E$241,">="&A7,Recruitment_Data!E$2:E$241,"<"&EDATE(A7,1),Recruitment_Data!J$2:J$241,"Hired") | C7: =IFERROR(AVERAGEIFS(Recruitment_Data!L$2:L$241,Recruitment_Data!E$2:E$241,">="&A7,Recruitment_Data!E$2:E$241,"<"&EDATE(A7,1),Recruitment_Data!J$2:J$241,"Hired"),0) | D7: =SUMIFS(Recruitment_Data!I$2:I$241,Recruitment_Data!E$2:E$241,">="&A7,Recruitment_Data!E$2:E$241,"<"&EDATE(A7,1),Recruitment_Data!J$2:J$241,"Hired")
A8: 45839 | B8: =COUNTIFS(Recruitment_Data!E$2:E$241,">="&A8,Recruitment_Data!E$2:E$241,"<"&EDATE(A8,1),Recruitment_Data!J$2:J$241,"Hired") | C8: =IFERROR(AVERAGEIFS(Recruitment_Data!L$2:L$241,Recruitment_Data!E$2:E$241,">="&A8,Recruitment_Data!E$2:E$241,"<"&EDATE(A8,1),Recruitment_Data!J$2:J$241,"Hired"),0) | D8: =SUMIFS(Recruitment_Data!I$2:I$241,Recruitment_Data!E$2:E$241,">="&A8,Recruitment_Data!E$2:E$241,"<"&EDATE(A8,1),Recruitment_Data!J$2:J$241,"Hired")
A9: 45870 | B9: =COUNTIFS(Recruitment_Data!E$2:E$241,">="&A9,Recruitment_Data!E$2:E$241,"<"&EDATE(A9,1),Recruitment_Data!J$2:J$241,"Hired") | C9: =IFERROR(AVERAGEIFS(Recruitment_Data!L$2:L$241,Recruitment_Data!E$2:E$241,">="&A9,Recruitment_Data!E$2:E$241,"<"&EDATE(A9,1),Recruitment_Data!J$2:J$241,"Hired"),0) | D9: =SUMIFS(Recruitment_Data!I$2:I$241,Recruitment_Data!E$2:E$241,">="&A9,Recruitment_Data!E$2:E$241,"<"&EDATE(A9,1),Recruitment_Data!J$2:J$241,"Hired")
A10: 45901 | B10: =COUNTIFS(Recruitment_Data!E$2:E$241,">="&A10,Recruitment_Data!E$2:E$241,"<"&EDATE(A10,1),Recruitment_Data!J$2:J$241,"Hired") | C10: =IFERROR(AVERAGEIFS(Recruitment_Data!L$2:L$241,Recruitment_Data!E$2:E$241,">="&A10,Recruitment_Data!E$2:E$241,"<"&EDATE(A10,1),Recruitment_Data!J$2:J$241,"Hired"),0) | D10: =SUMIFS(Recruitment_Data!I$2:I$241,Recruitment_Data!E$2:E$241,">="&A10,Recruitment_Data!E$2:E$241,"<"&EDATE(A10,1),Recruitment_Data!J$2:J$241,"Hired")
A11: 45931 | B11: =COUNTIFS(Recruitment_Data!E$2:E$241,">="&A11,Recruitment_Data!E$2:E$241,"<"&EDATE(A11,1),Recruitment_Data!J$2:J$241,"Hired") | C11: =IFERROR(AVERAGEIFS(Recruitment_Data!L$2:L$241,Recruitment_Data!E$2:E$241,">="&A11,Recruitment_Data!E$2:E$241,"<"&EDATE(A11,1),Recruitment_Data!J$2:J$241,"Hired"),0) | D11: =SUMIFS(Recruitment_Data!I$2:I$241,Recruitment_Data!E$2:E$241,">="&A11,Recruitment_Data!E$2:E$241,"<"&EDATE(A11,1),Recruitment_Data!J$2:J$241,"Hired")
A12: 45962 | B12: =COUNTIFS(Recruitment_Data!E$2:E$241,">="&A12,Recruitment_Data!E$2:E$241,"<"&EDATE(A12,1),Recruitment_Data!J$2:J$241,"Hired") | C12: =IFERROR(AVERAGEIFS(Recruitment_Data!L$2:L$241,Recruitment_Data!E$2:E$241,">="&A12,Recruitment_Data!E$2:E$241,"<"&EDATE(A12,1),Recruitment_Data!J$2:J$241,"Hired"),0) | D12: =SUMIFS(Recruitment_Data!I$2:I$241,Recruitment_Data!E$2:E$241,">="&A12,Recruitment_Data!E$2:E$241,"<"&EDATE(A12,1),Recruitment_Data!J$2:J$241,"Hired")
A13: 45992 | B13: =COUNTIFS(Recruitment_Data!E$2:E$241,">="&A13,Recruitment_Data!E$2:E$241,"<"&EDATE(A13,1),Recruitment_Data!J$2:J$241,"Hired") | C13: =IFERROR(AVERAGEIFS(Recruitment_Data!L$2:L$241,Recruitment_Data!E$2:E$241,">="&A13,Recruitment_Data!E$2:E$241,"<"&EDATE(A13,1),Recruitment_Data!J$2:J$241,"Hired"),0) | D13: =SUMIFS(Recruitment_Data!I$2:I$241,Recruitment_Data!E$2:E$241,">="&A13,Recruitment_Data!E$2:E$241,"<"&EDATE(A13,1),Recruitment_Data!J$2:J$241,"Hired")

Sheet Top_10_Longest_Cases
A1: Rank | B1: Candidate ID | C1: Source | D1: Department | E1: Role | F1: Time-to-Hire | G1: Hiring Cost (₹) | H1: Status
A2: 1 | B2: =INDEX(Recruitment_Data!$A$2:$A$241,MATCH(F2,Recruitment_Data!$L$2:$L$241,0)) | C2: =INDEX(Recruitment_Data!$B$2:$B$241,MATCH(F2,Recruitment_Data!$L$2:$L$241,0)) | D2: =INDEX(Recruitment_Data!$C$2:$C$241,MATCH(F2,Recruitment_Data!$L$2:$L$241,0)) | E2: =INDEX(Recruitment_Data!$D$2:$D$241,MATCH(F2,Recruitment_Data!$L$2:$L$241,0)) | F2: =LARGE(Recruitment_Data!$L$2:$L$241,A2) | G2: =INDEX(Recruitment_Data!$I$2:$I$241,MATCH(F2,Recruitment_Data!$L$2:$L$241,0)) | H2: =INDEX(Recruitment_Data!$J$2:$J$241,MATCH(F2,Recruitment_Data!$L$2:$L$241,0))
A3: 2 | B3: =INDEX(Recruitment_Data!$A$2:$A$241,MATCH(F3,Recruitment_Data!$L$2:$L$241,0)) | C3: =INDEX(Recruitment_Data!$B$2:$B$241,MATCH(F3,Recruitment_Data!$L$2:$L$241,0)) | D3: =INDEX(Recruitment_Data!$C$2:$C$241,MATCH(F3,Recruitment_Data!$L$2:$L$241,0)) | E3: =INDEX(Recruitment_Data!$D$2:$D$241,MATCH(F3,Recruitment_Data!$L$2:$L$241,0)) | F3: =LARGE(Recruitment_Data!$L$2:$L$241,A3) | G3: =INDEX(Recruitment_Data!$I$2:$I$241,MATCH(F3,Recruitment_Data!$L$2:$L$241,0)) | H3: =INDEX(Recruitment_Data!$J$2:$J$241,MATCH(F3,Recruitment_Data!$L$2:$L$241,0))
A4: 3 | B4: =INDEX(Recruitment_Data!$A$2:$A$241,MATCH(F4,Recruitment_Data!$L$2:$L$241,0)) | C4: =INDEX(Recruitment_Data!$B$2:$B$241,MATCH(F4,Recruitment_Data!$L$2:$L$241,0)) | D4: =INDEX(Recruitment_Data!$C$2:$C$241,MATCH(F4,Recruitment_Data!$L$2:$L$241,0)) | E4: =INDEX(Recruitment_Data!$D$2:$D$241,MATCH(F4,Recruitment_Data!$L$2:$L$241,0)) | F4: =LARGE(Recruitment_Data!$L$2:$L$241,A4) | G4: =INDEX(Recruitment_Data!$I$2:$I$241,MATCH(F4,Recruitment_Data!$L$2:$L$241,0)) | H4: =INDEX(Recruitment_Data!$J$2:$J$241,MATCH(F4,Recruitment_Data!$L$2:$L$241,0))
A5: 4 | B5: =INDEX(Recruitment_Data!$A$2:$A$241,MATCH(F5,Recruitment_Data!$L$2:$L$241,0)) | C5: =INDEX(Recruitment_Data!$B$2:$B$241,MATCH(F5,Recruitment_Data!$L$2:$L$241,0)) | D5: =INDEX(Recruitment_Data!$C$2:$C$241,MATCH(F5,Recruitment_Data!$L$2:$L$241,0)) | E5: =INDEX(Recruitment_Data!$D$2:$D$241,MATCH(F5,Recruitment_Data!$L$2:$L$241,0)) | F5: =LARGE(Recruitment_Data!$L$2:$L$241,A5) | G5: =INDEX(Recruitment_Data!$I$2:$I$241,MATCH(F5,Recruitment_Data!$L$2:$L$241,0)) | H5: =INDEX(Recruitment_Data!$J$2:$J$241,MATCH(F5,Recruitment_Data!$L$2:$L$241,0))
A6: 5 | B6: =INDEX(Recruitment_Data!$A$2:$A$241,MATCH(F6,Recruitment_Data!$L$2:$L$241,0)) | C6: =INDEX(Recruitment_Data!$B$2:$B$241,MATCH(F6,Recruitment_Data!$L$2:$L$241,0)) | D6: =INDEX(Recruitment_Data!$C$2:$C$241,MATCH(F6,Recruitment_Data!$L$2:$L$241,0)) | E6: =INDEX(Recruitment_Data!$D$2:$D$241,MATCH(F6,Recruitment_Data!$L$2:$L$241,0)) | F6: =LARGE(Recruitment_Data!$L$2:$L$241,A6) | G6: =INDEX(Recruitment_Data!$I$2:$I$241,MATCH(F6,Recruitment_Data!$L$2:$L$241,0)) | H6: =INDEX(Recruitment_Data!$J$2:$J$241,MATCH(F6,Recruitment_Data!$L$2:$L$241,0))
A7: 6 | B7: =INDEX(Recruitment_Data!$A$2:$A$241,MATCH(F7,Recruitment_Data!$L$2:$L$241,0)) | C7: =INDEX(Recruitment_Data!$B$2:$B$241,MATCH(F7,Recruitment_Data!$L$2:$L$241,0)) | D7: =INDEX(Recruitment_Data!$C$2:$C$241,MATCH(F7,Recruitment_Data!$L$2:$L$241,0)) | E7: =INDEX(Recruitment_Data!$D$2:$D$241,MATCH(F7,Recruitment_Data!$L$2:$L$241,0)) | F7: =LARGE(Recruitment_Data!$L$2:$L$241,A7) | G7: =INDEX(Recruitment_Data!$I$2:$I$241,MATCH(F7,Recruitment_Data!$L$2:$L$241,0)) | H7: =INDEX(Recruitment_Data!$J$2:$J$241,MATCH(F7,Recruitment_Data!$L$2:$L$241,0))
A8: 7 | B8: =INDEX(Recruitment_Data!$A$2:$A$241,MATCH(F8,Recruitment_Data!$L$2:$L$241,0)) | C8: =INDEX(Recruitment_Data!$B$2:$B$241,MATCH(F8,Recruitment_Data!$L$2:$L$241,0)) | D8: =INDEX(Recruitment_Data!$C$2:$C$241,MATCH(F8,Recruitment_Data!$L$2:$L$241,0)) | E8: =INDEX(Recruitment_Data!$D$2:$D$241,MATCH(F8,Recruitment_Data!$L$2:$L$241,0)) | F8: =LARGE(Recruitment_Data!$L$2:$L$241,A8) | G8: =INDEX(Recruitment_Data!$I$2:$I$241,MATCH(F8,Recruitment_Data!$L$2:$L$241,0)) | H8: =INDEX(Recruitment_Data!$J$2:$J$241,MATCH(F8,Recruitment_Data!$L$2:$L$241,0))
A9: 8 | B9: =INDEX(Recruitment_Data!$A$2:$A$241,MATCH(F9,Recruitment_Data!$L$2:$L$241,0)) | C9: =INDEX(Recruitment_Data!$B$2:$B$241,MATCH(F9,Recruitment_Data!$L$2:$L$241,0)) | D9: =INDEX(Recruitment_Data!$C$2:$C$241,MATCH(F9,Recruitment_Data!$L$2:$L$241,0)) | E9: =INDEX(Recruitment_Data!$D$2:$D$241,MATCH(F9,Recruitment_Data!$L$2:$L$241,0)) | F9: =LARGE(Recruitment_Data!$L$2:$L$241,A9) | G9: =INDEX(Recruitment_Data!$I$2:$I$241,MATCH(F9,Recruitment_Data!$L$2:$L$241,0)) | H9: =INDEX(Recruitment_Data!$J$2:$J$241,MATCH(F9,Recruitment_Data!$L$2:$L$241,0))
A10: 9 | B10: =INDEX(Recruitment_Data!$A$2:$A$241,MATCH(F10,Recruitment_Data!$L$2:$L$241,0)) | C10: =INDEX(Recruitment_Data!$B$2:$B$241,MATCH(F10,Recruitment_Data!$L$2:$L$241,0)) | D10: =INDEX(Recruitment_Data!$C$2:$C$241,MATCH(F10,Recruitment_Data!$L$2:$L$241,0)) | E10: =INDEX(Recruitment_Data!$D$2:$D$241,MATCH(F10,Recruitment_Data!$L$2:$L$241,0)) | F10: =LARGE(Recruitment_Data!$L$2:$L$241,A10) | G10: =INDEX(Recruitment_Data!$I$2:$I$241,MATCH(F10,Recruitment_Data!$L$2:$L$241,0)) | H10: =INDEX(Recruitment_Data!$J$2:$J$241,MATCH(F10,Recruitment_Data!$L$2:$L$241,0))
A11: 10 | B11: =INDEX(Recruitment_Data!$A$2:$A$241,MATCH(F11,Recruitment_Data!$L$2:$L$241,0)) | C11: =INDEX(Recruitment_Data!$B$2:$B$241,MATCH(F11,Recruitment_Data!$L$2:$L$241,0)) | D11: =INDEX(Recruitment_Data!$C$2:$C$241,MATCH(F11,Recruitment_Data!$L$2:$L$241,0)) | E11: =INDEX(Recruitment_Data!$D$2:$D$241,MATCH(F11,Recruitment_Data!$L$2:$L$241,0)) | F11: =LARGE(Recruitment_Data!$L$2:$L$241,A11) | G11: =INDEX(Recruitment_Data!$I$2:$I$241,MATCH(F11,Recruitment_Data!$L$2:$L$241,0)) | H11: =INDEX(Recruitment_Data!$J$2:$J$241,MATCH(F11,Recruitment_Data!$L$2:$L$241,0))

Sheet What_If_Scenarios
A1: Scenario | B1: Assumption | C1: Input | D1: Expected Effect | E1: Metric
A2: Scenario 1 | B2: Reduce Interview-to-Offer drop-off by 20% | C2: 0.2 | D2: More candidates reach Offer | E2: Application-to-Hire Ratio / Cost-per-Hire
A3: Scenario 2 | B3: Increase referral hiring by 15% | C3: 0.15 | D3: More hires from Referral | E3: Conversion / Cost-per-Hire
A4: Scenario 3 | B4: Reduce average Time-to-Hire by 5 days | C4: 5 | D4: Faster recruitment cycle | E4: Time-to-Hire / Cost-per-Hire

Sheet Recruitment Dashboard
A1: RECRUITMENT FUNNEL EFFICIENCY ANALYZER
A2: HR Recruitment Analytics | INR ₹ | Excel / Power BI ready
A4: Total Candidates | C4: Hires | E4: Application-to-Hire | G4: Avg Time-to-Hire | I4: Cost-per-Hire
A5: =KPI_Summary!B2 | C5: =KPI_Summary!B3 | E5: =KPI_Summary!B4 | G5: =KPI_Summary!B5 | I5: =KPI_Summary!B7
A7: Offer Acceptance
A8: =KPI_Summary!B8
A11: Source | C11: Department | E11: Stage | G11: Final Status
A12: □ Job Portal | C12: □ IT | E12: □ Applied | G12: □ Hired
A13: □ Referral | C13: □ Finance | E13: □ Screened | G13: □ Rejected
A14: □ LinkedIn | C14: □ HR | E14: □ Interviewed
A15: □ Campus | C15: □ Sales | E15: □ Offered
C16: □ Operations | E16: □ Hired
C17: □ Marketing | E17: □ Rejected
A53: Candidate ID | B53: Source | C53: Department | D53: Role | E53: Time-to-Hire | F53: Hiring Cost (₹)
A54: =Top_10_Longest_Cases!B2 | B54: =Top_10_Longest_Cases!C2 | C54: =Top_10_Longest_Cases!D2 | D54: =Top_10_Longest_Cases!E2 | E54: =Top_10_Longest_Cases!F2 | F54: =Top_10_Longest_Cases!G2
A55: =Top_10_Longest_Cases!B3 | B55: =Top_10_Longest_Cases!C3 | C55: =Top_10_Longest_Cases!D3 | D55: =Top_10_Longest_Cases!E3 | E55: =Top_10_Longest_Cases!F3 | F55: =Top_10_Longest_Cases!G3
A56: =Top_10_Longest_Cases!B4 | B56: =Top_10_Longest_Cases!C4 | C56: =Top_10_Longest_Cases!D4 | D56: =Top_10_Longest_Cases!E4 | E56: =Top_10_Longest_Cases!F4 | F56: =Top_10_Longest_Cases!G4
A57: =Top_10_Longest_Cases!B5 | B57: =Top_10_Longest_Cases!C5 | C57: =Top_10_Longest_Cases!D5 | D57: =Top_10_Longest_Cases!E5 | E57: =Top_10_Longest_Cases!F5 | F57: =Top_10_Longest_Cases!G5
A58: =Top_10_Longest_Cases!B6 | B58: =Top_10_Longest_Cases!C6 | C58: =Top_10_Longest_Cases!D6 | D58: =Top_10_Longest_Cases!E6 | E58: =Top_10_Longest_Cases!F6 | F58: =Top_10_Longest_Cases!G6
A59: =Top_10_Longest_Cases!B7 | B59: =Top_10_Longest_Cases!C7 | C59: =Top_10_Longest_Cases!D7 | D59: =Top_10_Longest_Cases!E7 | E59: =Top_10_Longest_Cases!F7 | F59: =Top_10_Longest_Cases!G7
A60: =Top_10_Longest_Cases!B8 | B60: =Top_10_Longest_Cases!C8 | C60: =Top_10_Longest_Cases!D8 | D60: =Top_10_Longest_Cases!E8 | E60: =Top_10_Longest_Cases!F8 | F60: =Top_10_Longest_Cases!G8
A61: =Top_10_Longest_Cases!B9 | B61: =Top_10_Longest_Cases!C9 | C61: =Top_10_Longest_Cases!D9 | D61: =Top_10_Longest_Cases!E9 | E61: =Top_10_Longest_Cases!F9 | F61: =Top_10_Longest_Cases!G9
A62: =Top_10_Longest_Cases!B10 | B62: =Top_10_Longest_Cases!C10 | C62: =Top_10_Longest_Cases!D10 | D62: =Top_10_Longest_Cases!E10 | E62: =Top_10_Longest_Cases!F10 | F62: =Top_10_Longest_Cases!G10
A63: =Top_10_Longest_Cases!B11 | B63: =Top_10_Longest_Cases!C11 | C63: =Top_10_Longest_Cases!D11 | D63: =Top_10_Longest_Cases!E11 | E63: =Top_10_Longest_Cases!F11 | F63: =Top_10_Longest_Cases!G11

Sheet Instructions
A1: PROJECT TITLE | B1: Recruitment Funnel Efficiency Analyzer
A2: Objective | B2: Analyze recruitment from applications to offers using conversion rates, time-to-hire, cost-per-hire and bottleneck analysis.
A3: Dataset | B3: 240 sample recruitment records; requirement is 200+.
A4: Stage Duration | B4: Stage Exit Date − Stage Entry Date.
A5: Application-to-Hire Ratio | B5: Hired ÷ Applied.
A6: Stage Conversion % | B6: Candidates progressed ÷ candidates entered stage.
A7: Time-to-Hire | B7: Hired candidate exit date − Applied date.
A8: Cost-per-Hire | B8: Total Hiring Cost ÷ Number of Hires.
A9: Offer Acceptance Rate | B9: Offers Accepted ÷ Offers Given.
A10: Dashboard | B10: Funnel, drop-off %, hires by source, time-to-hire trend, cost-per-hire by source, and department conversion.
A11: Top 10 | B11: Longest recruitment cases with Candidate ID and duration.
A12: What-if 1 | B12: Reduce Interview-to-Offer drop-off by 20%.
... A15: Currency | B15: Recruitment cost values use INR (₹).
